<?xml version='1.0'?>
<sdf version='1.4'>
  <model name="robonaldo">
    <static>false</static>
    <link name="chassis"> 
      <pose>0 0 .09886 0 0 0</pose>
      <!--inertial>
        <mass>23</mass>
      </inertial-->
      <collision name="collision">
        <geometry>
          <box>
            <size>.308864 .217932 .13335</size>
          </box>
        </geometry>
      </collision>

      <visual name="visual">
        <geometry>
          <box>
            <size>.308864 .217932 .13335</size>
          </box>
        </geometry>
      </visual>
      <collision name="caster_collision">
        <pose>-0.2 0 -0.05 0 0 0</pose>
        <!--inertial><mass>6.0</mass></inertial-->

        <geometry>
          <sphere>
            <radius>.05</radius>
          </sphere>
        </geometry>
        <surface>
          <friction>
            <ode>
              <mu>0</mu>
              <mu2>0</mu2>
              <slip1>1.0</slip1>
              <slip2>1.0</slip2>
            </ode>
          </friction>
        </surface>
      </collision>

      <visual name="caster_visual">
        <pose>-0.2 0 -0.05 0 0 0</pose>
        <!--inertial><mass>6.0</mass></inertial-->
        
        <geometry>
          <sphere>
            <radius>.05</radius>
          </sphere>
        </geometry>
        <!--To make caster wheel heavier, use flesh_mass_fraction-->
        <!--surface>
          <soft_contact>
            <dart>
              <flesh_mass_fraction>.5</flesh_mass_fraction>
            </dart>
          </soft_contact>
        </surface-->
      </visual>

    </link>

    <link name="left_wheel">
      <pose>0 0.1332738 0.1 0 1.5707 1.5707</pose>
      <collision name="collision">
        <geometry>
          <cylinder>
            <radius>.1008888</radius>
            <length>.0486156</length>
          </cylinder>
        </geometry>
      </collision>
      <visual name="visual">
        <geometry>
          <cylinder>
            <radius>.1008888</radius>
            <length>.0486156</length>
          </cylinder>
        </geometry>
      </visual>
    </link>

    <link name="right_wheel">
      <pose>0 -0.1332738 0.1 0 1.5707 1.5707</pose>
      <collision name="collision">
        <geometry>
          <cylinder>
            <radius>.1008888</radius>
            <length>.0486156</length>
          </cylinder>
        </geometry>
      </collision>
      <visual name="visual">
        <geometry>
          <cylinder>
            <radius>.1008888</radius>
            <length>.0486156</length>
          </cylinder>
        </geometry>
      </visual>
    </link>

    <joint type="revolute" name="left_wheel_hinge">
      <pose>0 0 -0.03 0 0 0</pose>
      <child>left_wheel</child>
      <parent>chassis</parent>
      <axis>
        <xyz>0 1 0</xyz>
      </axis>
    </joint>
    <joint type="revolute" name="right_wheel_hinge">
      <pose>0 0 0.03 0 0 0</pose>
      <child>right_wheel</child>
      <parent>chassis</parent>
      <axis>
        <xyz>0 1 0</xyz>
      </axis>
    </joint>

  </model>
</sdf>
